Workbook
Name ActivosTotales: Cálculos!$B$9
Name Imprimir_Área: [1]Dashboard!$A$1:$H$19
Name PasivosTotales: tblNoAsegurado[[#Totals],[Tope]]
Name PatrimonioNeto: Cálculos!$B$9

Sheet 2026
A1: NºPer. | B1: DNI | C1: Nombre | D1: Desde* | E1: Hasta* | F1: NºProp. | G1: Nombrto/Contrato | H1: Razón de Alta | I1: Plaza | J1: RJ | K1: Cláusula | L1: T.Nombrto | M1: Días | N1: Puesto trabajo | O1: GFH | P1: Dirección | Q1: NºPer.Sust | R1: DNI.Sust | S1: Nombre Sustituido | T1: Puesto Sustitutido | U1: Hasta*Usada | V1: F_Necesidad | W1: Necesidad
A2: 160888 | B2: 43832660L | C2: LEON GONZALEZ, PATRICIA | D2: 46023 | E2: 46033 | F2: 169690 | G2: TEMPORAL. T. COM. INTER. N. ESTA | H2: INTERINO POR VACANTE | I2: FEA ENDOCRINOLOGÍA Y N | J2: E | K2: I_9_1a | L2: N91a | M2: 11 | N2: FEA ENDOCRINOLOGÍA Y NUTRICIÓN | O2: P.MÉDICO ENDOCRINOLOGÍA | P2: DIRECCIÓN MÉDICA | Q2: 0 | U2: 46033
A3: 187533 | B3: 45456485K | C3: MASCAREÑO PEREZ, MARIA ISABEL | D3: 46023 | E3: 46033 | F3: 153022 | G3: TEMPORAL. T. COM. INTER. N. ESTA | H3: INTERINO POR VACANTE | I3: MEDICO/A URGENCIA HOSPITALARIA | J3: E | K3: I_9_1a | L3: N91a | M3: 11 | N3: MÉDICO URGENCIA HOSPITALARIA | O3: P.MÉDICO GERIATRÍA HOSP.NORTE | P3: DIRECCIÓN MÉDICA | Q3: 0 | U3: 46033
A4: 236228 | B4: 78646939A | C4: REYES GONZALEZ CASANOVA, PAULA | D4: 46023 | E4: 46033 | F4: 169694 | G4: TEMPORAL. T. COM. INTER. N. ESTA | H4: INTERINO POR VACANTE | I4: FEA HEMATOLOGÍA Y HEMOTERAPIA | J4: E | K4: I_9_1a | L4: N91a | M4: 11 | N4: FEA HEMATOLOGIA Y HEMOTERAPIA | O4: P.MÉDICO HEMATOLOGÍA CLÍNICA | P4: DIRECCIÓN MÉDICA | Q4: 0 | U4: 46033
A5: 225280 | B5: 78717263Q | C5: TOSCO NUÑEZ, TOMAS | D5: 46023 | E5: 46033 | F5: 169702 | G5: TEMPORAL. T. COM. INTER. N. ESTA | H5: INTERINO POR VACANTE | I5: FEA MICROBIOLOGÍA Y PARASITOLOGÍA | J5: E | K5: I_9_1a | L5: N91a | M5: 11 | N5: FEA MICROBIOLOGÍA Y PARASITOLOGÍA | O5: P.MÉDICO MICROBIOLOGÍA Y CONTROL INFECCI | P5: DIRECCIÓN MÉDICA | Q5: 0 | U5: 46033
A6: 349426 | B6: 77147626Z | C6: BAEZA RUIZ, ADRIAN | D6: 46023 | E6: 46033 | F6: 169719 | G6: TEMPORAL. T. COM. INTER. N. ESTA | H6: INTERINO POR VACANTE | I6: FEA NEUMOLOGÍA | J6: E | K6: I_9_1a | L6: N91a | M6: 11 | N6: FEA NEUMOLOGÍA | O6: P.MÉDICO NEUMOLOGÍA | P6: DIRECCIÓN MÉDICA | Q6: 0 | U6: 46033
A7: 389597 | B7: 78724201P | C7: HERNANDEZ GARCIA, VERONICA SARAY | D7: 46023 | E7: 46033 | F7: 152987 | G7: TEMPORAL. T. COM. INTER. N. ESTA | H7: INTERINO POR VACANTE | I7: FEA NEUMOLOGÍA | J7: E | K7: I_9_1a | L7: N91a | M7: 11 | N7: FEA NEUMOLOGÍA | O7: P.MÉDICO NEUMOLOGÍA | P7: DIRECCIÓN MÉDICA | Q7: 0 | U7: 46033
A8: 229588 | B8: 78642879Z | C8: MESA LEON, NELSON | D8: 46023 | E8: 46033 | F8: 169720 | G8: TEMPORAL. T. COM. INTER. N. ESTA | H8: INTERINO POR VACANTE | I8: FEA NEUMOLOGÍA | J8: E | K8: I_9_1a | L8: N91a | M8: 11 | N8: FEA NEUMOLOGÍA | O8: P.MÉDICO NEUMOLOGÍA | P8: DIRECCIÓN MÉDICA | Q8: 0 | U8: 46033
A9: 399975 | B9: 72894206F | C9: ESCALADA PELLITERO, SILVIA | D9: 46023 | E9: 46035 | F9: 153000 | G9: TEMPORAL. T. COM. INTER. N. ESTA | H9: INTERINO POR VACANTE | I9: FEA PEDIATRÍA | J9: E | K9: I_9_1a | L9: N91a | M9: 13 | N9: FEA PEDIATRÍA | O9: P.MÉDICO PEDIATRÍA | P9: DIRECCIÓN MÉDICA | Q9: 0 | U9: 46035
A10: 378335 | B10: 51148047A | C10: PEREZ DE ARMAS, PAULA | D10: 46023 | E10: 46037 | F10: 169718 | G10: TEMPORAL. T. COM. INTER. N. ESTA | H10: INTERINO POR VACANTE | I10: FEA NEUMOLOGÍA | J10: E | K10: I_9_1a | L10: N91a | M10: 15 | N10: FEA NEUMOLOGÍA | O10: P.MÉDICO NEUMOLOGÍA | P10: DIRECCIÓN MÉDICA | Q10: 0 | U10: 46037
A11: 211865 | B11: 54112637P | C11: ALFONSO ALVAREZ, MARTA | D11: 46023 | E11: 46043 | F11: 155903 | G11: TEMPORAL. T. COM. INTER. N. ESTA | H11: INTERINO POR VACANTE | I11: TÉC ESPECIALISTA / RADIODIAGNÓSTICO | J11: E | K11: I_9_1a | L11: N91a | M11: 21 | N11: TÉCNICO ESPECIALISTA RADIODIAGNÓSTICO | O11: AREA.ENFERMERIA - CAE LA LAGUNA-GENETO | P11: DIRECCIÓN DE ENFERMERÍA | Q11: 0 | U11: 46043
A12: 218739 | B12: 78725868L | C12: RODRIGUEZ GONZALEZ, DARA | D12: 46023 | E12: 46048 | F12: 0 | G12: TEMPORAL. T. COM. INTER. N. ESTA | H12: INTERINO POR VACANTE | I12: FEA BIOQUÍMICA CLÍNICA | J12: E | K12: I_9_1a | L12: N91a | M12: 26 | N12: FEA BIOQUÍMICA CLÍNICA | O12: P.MÉDICO FISIOLOGÍA Y BIOQUÍMICA | P12: DIRECCIÓN MÉDICA | Q12: 0 | U12: 46048
A13: 359613 | B13: 70253317R | C13: MUÑOZ TORRERO MARTIN, ANA | D13: 46023 | E13: 46053 | F13: 170603 | G13: TEMPORAL. T. COM. INTER. N. ESTA | H13: INTERINO POR VACANTE | I13: ENFERMERO/A | J13: E | K13: I_9_1a | L13: N91a | M13: 31 | N13: ENFERMERA/O | O13: UDAD.DE RECUPERACIÓN DE QUIRÓFANO | P13: DIRECCIÓN DE ENFERMERÍA | Q13: 0 | U13: 46053
... A89: 219892 | B89: 43356801F | C89: MOLINA GONZALEZ, DELFINA | D89: 46023 | E89: 46146 | F89: 169789 | G89: TEMPORAL. T. COM. INTER. N. ESTA | H89: INTERINO POR VACANTE | I89: TÉC ESPECIALISTA / LABORATORIO | J89: E | K89: I_9_1a | L89: N91a | M89: 124 | N89: TÉCNICO ESPECIALISTA LABORATORIO | O89: LABORATORIO CENTRAL | P89: DIRECCIÓN DE ENFERMERÍA | Q89: 0 | U89: 46146
A90: 332898 | B90: 45443450G | C90: ROSA GONZALEZ, MARIA TERESA.DE.LA. | D90: 46023 | E90: 46146 | F90: 154032 | G90: TEMPORAL. T. COM. INTER. N. ESTA | H90: INTERINO POR VACANTE | I90: TÉC ESPECIALISTA / RADIODIAGNÓSTICO | J90: E | K90: I_9_1a | L90: N91a | M90: 124 | N90: TÉCNICO ESPECIALISTA RADIODIAGNÓSTICO | O90: RADIODIAGNOSTICO | P90: DIRECCIÓN DE ENFERMERÍA | Q90: 0 | U90: 46146 | V90: 46387 | W90: =_xlfn.DAYS(V90,U90) -> 241
A91: 236495 | B91: 09290030P | C91: HORTELANO HORTELANO, CELIA | D91: 46023 | E91: 46147 | F91: 162706 | G91: TEMPORAL. T. COM. INTER. N. ESTA | H91: INTERINO POR VACANTE | I91: FEA PSICOLOGÍA CLÍNICA | J91: E | K91: I_9_1a | L91: N91a | M91: 125 | N91: FEA PSICOLOGÍA CLÍNICA | O91: P.MÉDICO PSIQUIATRÍA | P91: DIRECCIÓN MÉDICA | Q91: 0 | U91: 46147
A92: 223768 | B92: 78722483S | C92: ARMAS RODRIGUEZ, INGRID | D92: 46023 | E92: 46152 | F92: 161163 | G92: TEMPORAL. T. COM. INTER. N. ESTA | H92: INTERINO POR VACANTE | I92: AUXILIAR DE ENFERMERÍA | J92: E | K92: I_9_1a | L92: N91a | M92: 130 | N92: AUXILIAR DE ENFERMERÍA | O92: URGENCIAS | P92: DIRECCIÓN DE ENFERMERÍA | Q92: 0 | U92: 46152
A93: 229557 | B93: 43832509Y | C93: FAJARDO RODRIGUEZ, DIEGO | D93: 46113 | E93: 46154 | F93: 177708 | G93: TEMPORAL. T. COM. INTER. N. ESTA | H93: INTERINO POR VACANTE | I93: COCINERO/A | J93: E | K93: I_9_1a | L93: N91a | M93: 42 | N93: COCINERO | O93: COCINA | P93: Dirección Servicios Generales | Q93: 0 | U93: 46154
A94: 238495 | B94: 43821391C | C94: PADRON CAMPOS, BEATRIZ | D94: 46023 | E94: 46156 | F94: 161545 | G94: TEMPORAL. T. COM. INTER. N. ESTA | H94: INTERINO POR VACANTE | I94: TÉCNICA/O AUXILIAR DE FARMACIA | J94: E | K94: I_9_1a | L94: N91a | M94: 134 | N94: TÉCNICA/O AUXILIAR DE FARMACIA | O94: ALMACÉN DE FARMACIA | P94: DIRECCIÓN DE ENFERMERÍA | Q94: 0 | U94: 46156
A95: 340820 | B95: 42057023M | C95: HERNANDEZ RODRIGUEZ, JOSE FRANCISCO | D95: 46023 | E95: 46161 | F95: 162751 | G95: TEMPORAL. T. COM. INTER. N. ESTA | H95: INTERINO POR VACANTE | I95: G ADMINISTRATIVO FUNCIÓN ADMINISTRATIVA | J95: E | K95: I_9_1a | L95: N91a | M95: 139 | N95: GRUPO ADMINISTRATIVO | O95: RECEPCIÓN DE POLICLÍNICA | P95: Dirección Planificación y Gestión RREE | Q95: 0 | U95: 46161
A96: 311640 | B96: 42077016B | C96: DELGADO SANTANA, MARIA NIEVES | D96: 46023 | E96: 46162 | F96: 149704 | G96: TEMPORAL. T. COM. INTER. N. ESTA | H96: INTERINO POR VACANTE | I96: G ADMINISTRATIVO FUNCIÓN ADMINISTRATIVA | J96: E | K96: I_9_1a | L96: N91a | M96: 140 | N96: GRUPO ADMINISTRATIVO | O96: COORDINACIÓN DE INFORMACIÓN | P96: GERENCIA | Q96: 0 | U96: 46162
A97: 284301 | B97: 43608597E | C97: SANCHEZ GUTIERREZ, DOMINGO | D97: 46023 | E97: 46165 | F97: 162756 | G97: TEMPORAL. T. COM. INTER. N. ESTA | H97: INTERINO POR VACANTE | I97: G ADMINISTRATIVO FUNCIÓN ADMINISTRATIVA | J97: E | K97: I_9_1a | L97: N91a | M97: 143 | N97: GRUPO ADMINISTRATIVO | O97: ADMISIÓN URGENCIAS | P97: DIRECCIÓN MÉDICA | Q97: 0 | U97: 46165
A98: 309724 | B98: 76883227T | C98: RAYA DURAN, MARIA | D98: 46023 | E98: 46173 | F98: 170581 | G98: TEMPORAL. T. COM. INTER. N. ESTA | H98: INTERINO POR VACANTE | I98: ENFERMERO/A | J98: E | K98: I_9_1a | L98: N91a | M98: 151 | N98: ENFERMERA/O | O98: PLANTA 2ª - HOSPITALIZACIÓN EDIF. D | P98: DIRECCIÓN DE ENFERMERÍA | Q98: 0 | U98: 46173
A99: 217287 | B99: 60685293T | C99: BRAVO LJUBETIC, LUCIANO ANDRES | D99: 46023 | E99: 46173 | F99: 150183 | G99: TEMPORAL. T. COM. INTER. N. ESTA | H99: INTERINO POR VACANTE | I99: FEA OFTALMOLOGÍA | J99: E | K99: I_9_1a | L99: N91a | M99: 151 | N99: FEA OFTALMOLOGÍA | O99: P.MÉDICO OFTALMOLOGÍA | P99: DIRECCIÓN MÉDICA | Q99: 0 | U99: 46173
A100: 250120 | B100: 78720481Z | C100: LARRAÑAGA FRAGOSO, PAULA CRISTINA | D100: 46023 | E100: 46173 | F100: 143101 | G100: TEMPORAL. T. COM. INTER. N. ESTA | H100: INTERINO POR VACANTE | I100: FEA OFTALMOLOGÍA | J100: E | K100: I_9_1a | L100: N91a | M100: 151 | N100: FEA OFTALMOLOGÍA | O100: P.MÉDICO OFTALMOLOGÍA | P100: DIRECCIÓN MÉDICA | Q100: 0 | U100: 46173
A101: 378965 | B101: 76262742D | C101: AYUSO SANCHEZ, CELIA | D101: 46023 | E101: 46181 | F101: 170729 | G101: TEMPORAL. T. COM. INTER. N. ESTA | H101: INTERINO POR VACANTE | I101: ENFERMERO/A | J101: E | K101: I_9_1a | L101: N91a | M101: 159 | N101: ENFERMERA/O | O101: URGENCIAS | P101: DIRECCIÓN DE ENFERMERÍA | Q101: 0 | U101: 46181
A102: 253583 | B102: 78699024Q | C102: FERNANDEZ ALVAREZ, PAULA | D102: 46023 | E102: 46187 | F102: 0 | G102: TEMPORAL. T. COM. INTER. N. ESTA | H102: INTERINO POR VACANTE | I102: TÉCNICO/A TITULADO/A MEDIO | J102: E | K102: I_9_1a | L102: N91a | M102: 165 | N102: PERSONAL TÉCNICO (G.MEDIO) | O102: CONSULTA OFTALMOLOGÍA | P102: DIRECCIÓN DE ENFERMERÍA | Q102: 0 | U102: 46187
... A822: 270579 | B822: 78630221Y | C822: HERNANDEZ MESA, NAYRA | D822: 46023 | E822: 46387 | F822: 161119 | G822: TEMPORAL. T. COM. INTER. N. ESTA | H822: INTERINO POR VACANTE | I822: AUXILIAR DE ENFERMERÍA | J822: E | K822: I_9_1a | L822: N91a | M822: 365 | N822: AUXILIAR DE ENFERMERÍA | O822: PLANTILLA VOLANTE | P822: DIRECCIÓN DE ENFERMERÍA | Q822: 0 | U822: 46387
A823: 390544 | B823: 78570401D | C823: LESTON RAMOS, JASMINA DEBORA | D823: 46023 | E823: 46387 | F823: 175506 | G823: TEMPORAL. T. COM. INTER. N. ESTA | H823: INTERINO POR VACANTE | I823: AUXILIAR DE ENFERMERÍA | J823: E | K823: I_9_1a | L823: N91a | M823: 365 | N823: AUXILIAR DE ENFERMERÍA | O823: PLANTILLA VOLANTE | P823: DIRECCIÓN DE ENFERMERÍA | Q823: 0 | U823: 46387 | V823: 46387 | W823: =_xlfn.DAYS(V823,U823) -> 0
A824: 231172 | B824: 43839287E | C824: LOPEZ MORENO, EDGAR | D824: 46023 | E824: 46387 | F824: 170787 | G824: TEMPORAL. T. COM. INTER. N. ESTA | H824: INTERINO POR VACANTE | I824: ENFERMERO/A | J824: E | K824: I_9_1a | L824: N91a | M824: 365 | N824: ENFERMERA/O | O824: PLANTILLA VOLANTE | P824: DIRECCIÓN DE ENFERMERÍA | Q824: 0 | U824: 46387 | V824: 46387 | W824: =_xlfn.DAYS(V824,U824) -> 0
A825: 375466 | B825: 43781282T | C825: MARTIN ALVAREZ, JOSE MANUEL | D825: 46023 | E825: 46387 | F825: 169960 | G825: TEMPORAL. T. COM. INTER. N. ESTA | H825: INTERINO POR VACANTE | I825: AUXILIAR DE ENFERMERÍA | J825: E | K825: I_9_1a | L825: N91a | M825: 365 | N825: AUXILIAR DE ENFERMERÍA | O825: PLANTILLA VOLANTE | P825: DIRECCIÓN DE ENFERMERÍA | Q825: 0 | U825: 46387 | V825: 46387 | W825: =_xlfn.DAYS(V825,U825) -> 0
A826: 245540 | B826: 48831594H | C826: MARTINEZ PALAO, FERNANDO | D826: 46023 | E826: 46387 | F826: 170779 | G826: TEMPORAL. T. COM. INTER. N. ESTA | H826: INTERINO POR VACANTE | I826: ENFERMERO/A | J826: E | K826: I_9_1a | L826: N91a | M826: 365 | N826: ENFERMERA/O | O826: PLANTILLA VOLANTE | P826: DIRECCIÓN DE ENFERMERÍA | Q826: 0 | U826: 46387 | V826: 46387 | W826: =_xlfn.DAYS(V826,U826) -> 0
A827: 295002 | B827: 45604885W | C827: MARTINEZ PARRA, JAIME | D827: 46023 | E827: 46387 | F827: 169748 | G827: TEMPORAL. T. COM. INTER. N. ESTA | H827: INTERINO POR VACANTE | I827: ENFERMERO/A | J827: E | K827: I_9_1a | L827: N91a | M827: 365 | N827: ENFERMERA/O | O827: PLANTILLA VOLANTE | P827: DIRECCIÓN DE ENFERMERÍA | Q827: 0 | U827: 46387 | V827: 46387 | W827: =_xlfn.DAYS(V827,U827) -> 0
A828: 377653 | B828: 49148476Y | C828: MORANO CORRALES, MARIA | D828: 46023 | E828: 46387 | F828: 170773 | G828: TEMPORAL. T. COM. INTER. N. ESTA | H828: INTERINO POR VACANTE | I828: ENFERMERO/A | J828: E | K828: I_9_1a | L828: N91a | M828: 365 | N828: ENFERMERA/O | O828: PLANTILLA VOLANTE | P828: DIRECCIÓN DE ENFERMERÍA | Q828: 0 | U828: 46387 | V828: 46387 | W828: =_xlfn.DAYS(V828,U828) -> 0
A829: 217022 | B829: 77020401W | C829: MORENO RUIZ, MINERVA | D829: 46023 | E829: 46387 | F829: 174405 | G829: TEMPORAL. T. COM. INTER. N. ESTA | H829: INTERINO POR VACANTE | I829: ENFERMERO/A | J829: E | K829: I_9_1a | L829: N91a | M829: 365 | N829: ENFERMERA/O | O829: PLANTILLA VOLANTE | P829: DIRECCIÓN DE ENFERMERÍA | Q829: 0 | U829: 46387 | V829: 46387 | W829: =_xlfn.DAYS(V829,U829) -> 0
A830: 213804 | B830: 54052098M | C830: NEGRIN RODRIGUEZ, ANDREA MARIA | D830: 46023 | E830: 46387 | F830: 162368 | G830: TEMPORAL. T. COM. INTER. N. ESTA | H830: INTERINO POR VACANTE | I830: ENFERMERO/A | J830: E | K830: I_9_1a | L830: N91a | M830: 365 | N830: ENFERMERA/O | O830: PLANTILLA VOLANTE | P830: DIRECCIÓN DE ENFERMERÍA | Q830: 0 | U830: 46387 | V830: 46387 | W830: =_xlfn.DAYS(V830,U830) -> 0
A831: 263906 | B831: 78680168C | C831: NUÑEZ SUAREZ, JUANA MARIA | D831: 46023 | E831: 46387 | F831: 161147 | G831: TEMPORAL. T. COM. INTER. N. ESTA | H831: INTERINO POR VACANTE | I831: AUXILIAR DE ENFERMERÍA | J831: E | K831: I_9_1a | L831: N91a | M831: 365 | N831: AUXILIAR DE ENFERMERÍA | O831: PLANTILLA VOLANTE | P831: DIRECCIÓN DE ENFERMERÍA | Q831: 0 | U831: 46387 | V831: 46387 | W831: =_xlfn.DAYS(V831,U831) -> 0
A832: 227504 | B832: 54108629W | C832: PADILLA HERNANDEZ, YAIZA | D832: 46023 | E832: 46387 | F832: 174286 | G832: TEMPORAL. T. COM. INTER. N. ESTA | H832: INTERINO POR VACANTE | I832: AUXILIAR DE ENFERMERÍA | J832: E | K832: I_9_1a | L832: N91a | M832: 365 | N832: AUXILIAR DE ENFERMERÍA | O832: PLANTILLA VOLANTE | P832: DIRECCIÓN DE ENFERMERÍA | Q832: 0 | U832: 46387 | V832: 46387 | W832: =_xlfn.DAYS(V832,U832) -> 0
A833: 200191 | B833: 43486246P | C833: PALENZUELA ALVAREZ, THALIA | D833: 46023 | E833: 46387 | F833: 174421 | G833: TEMPORAL. T. COM. INTER. N. ESTA | H833: INTERINO POR VACANTE | I833: ENFERMERO/A | J833: E | K833: I_9_1a | L833: N91a | M833: 365 | N833: ENFERMERA/O | O833: PLANTILLA VOLANTE | P833: DIRECCIÓN DE ENFERMERÍA | Q833: 0 | U833: 46387 | V833: 46387 | W833: =_xlfn.DAYS(V833,U833) -> 0
A834: 226972 | B834: 78624619Q | C834: PERDOMO PEREZ, MARIA YURENA | D834: 46023 | E834: 46387 | F834: 169913 | G834: TEMPORAL. T. COM. INTER. N. ESTA | H834: INTERINO POR VACANTE | I834: AUXILIAR DE ENFERMERÍA | J834: E | K834: I_9_1a | L834: N91a | M834: 365 | N834: AUXILIAR DE ENFERMERÍA | O834: PLANTILLA VOLANTE | P834: DIRECCIÓN DE ENFERMERÍA | Q834: 0 | U834: 46387 | V834: 46387 | W834: =_xlfn.DAYS(V834,U834) -> 0
...

Sheet Panel
B2: PANEL | G2: RESUMEN DE LA BOLSA NETO
B11: =125215+464271 -> 589486 | D11: =ActivosTotales -> 124526.32 | G11: =PasivosTotales -> 462712.01
B12: BOLSA NETO | D12: Bolsa I91c | G12: Bolsa I9B1a
D13: Dirección Planificación y Gestión RREE | G13: Dirección Planificación y Gestión RREE
D14: Dirección Enfermería | G14: Dirección Enfermería
D15: Dirección Ingeneria, Infraestrutura y Tecn. | G15: Dirección Ingeneria, Infraestrutura y Tecn.
D16: Dirección Servicios Generales | G16: Dirección Servicios Generales
D17: Dirección Médica | G17: Dirección Médica
D18: Dirección RRHH | G18: Dirección RRHH
D19: Gerencia | G19: Gerencia

Sheet I91c
B2: BOLSA I91c | I2: RESUMEN DE LA BOLSA NETO
D4: Bolsa I91c | E4: Tope | I4: Bolsa I91c | J4: Usados | K4: Resto | L4: Necesidad
D5: Gerencia | E5: 1940.8325 | I5: Gerencia | J5: =VLOOKUP(Bolsausados[[#This Row],[Bolsa I91c]],Cálculos!$D$4:$F$10,2,FALSE) -> 5583 | K5: =Bolsatope[[#This Row],[Tope]]-Bolsausados[[#This Row],[Usados]] -> -3642.1675 | L5: =VLOOKUP(Bolsausados[[#This Row],[Bolsa I91c]],Cálculos!$D$4:$F$10,3,FALSE) -> 1744
D6: Dirección Médica | E6: 23289.99 | I6: Dirección Médica | J6: =VLOOKUP(Bolsausados[[#This Row],[Bolsa I91c]],Cálculos!$D$4:$F$10,2,FALSE) -> 33969 | K6: =Bolsatope[[#This Row],[Tope]]-Bolsausados[[#This Row],[Usados]] -> -10679.01 | L6: =VLOOKUP(Bolsausados[[#This Row],[Bolsa I91c]],Cálculos!$D$4:$F$10,3,FALSE) -> 9089
D7: Dirección Enfermería | E7: 76506.365 | I7: DIRECCIÓN DE ENFERMERÍA | J7: =VLOOKUP(Bolsausados[[#This Row],[Bolsa I91c]],Cálculos!$D$4:$F$10,2,FALSE) -> 34607 | K7: =Bolsatope[[#This Row],[Tope]]-Bolsausados[[#This Row],[Usados]] -> 41899.365 | L7: =VLOOKUP(Bolsausados[[#This Row],[Bolsa I91c]],Cálculos!$D$4:$F$10,3,FALSE) -> 18822
D8: Dirección Planificación y Gestión RREE | E8: 6385.965 | I8: Dirección Planificación y Gestión RREE | J8: =VLOOKUP(Bolsausados[[#This Row],[Bolsa I91c]],Cálculos!$D$4:$F$10,2,FALSE) -> 5873 | K8: =Bolsatope[[#This Row],[Tope]]-Bolsausados[[#This Row],[Usados]] -> 512.965 | L8: =VLOOKUP(Bolsausados[[#This Row],[Bolsa I91c]],Cálculos!$D$4:$F$10,3,FALSE) -> 1698
D9: Dirección Ingenería, Infraestructuras y Tecnologías | E9: 3005.16 | I9: Dirección Ingeniería, Infraestructura y Tecnologías | J9: =VLOOKUP(Bolsausados[[#This Row],[Bolsa I91c]],Cálculos!$D$4:$F$10,2,FALSE) -> 8645 | K9: =Bolsatope[[#This Row],[Tope]]-Bolsausados[[#This Row],[Usados]] -> -5639.84 | L9: =VLOOKUP(Bolsausados[[#This Row],[Bolsa I91c]],Cálculos!$D$4:$F$10,3,FALSE) -> 4520
D10: Dirección Servicios Generales | E10: 11394.565 | I10: Dirección Servicios Generales | J10: =VLOOKUP(Bolsausados[[#This Row],[Bolsa I91c]],Cálculos!$D$4:$F$10,2,FALSE) -> 13679 | K10: =Bolsatope[[#This Row],[Tope]]-Bolsausados[[#This Row],[Usados]] -> -2284.435 | L10: =VLOOKUP(Bolsausados[[#This Row],[Bolsa I91c]],Cálculos!$D$4:$F$10,3,FALSE) -> 6317
D11: Dirección RRHH | E11: 2003.44 | I11: DIRECCIÓN DE RR.HH. | J11: =VLOOKUP(Bolsausados[[#This Row],[Bolsa I91c]],Cálculos!$D$4:$F$10,2,FALSE) -> 216 | K11: =Bolsatope[[#This Row],[Tope]]-Bolsausados[[#This Row],[Usados]] -> 1787.44 | L11: =VLOOKUP(Bolsausados[[#This Row],[Bolsa I91c]],Cálculos!$D$4:$F$10,3,FALSE) -> 149
B12: =ActivosTotales -> 124526.32 | D12: SUBTOTAL | E12: =SUBTOTAL(109,Bolsatope[Tope]) -> 124526.32 | I12: SUBTOTAL | J12: =SUBTOTAL(109,Bolsausados[Usados]) -> 102572 | K12: =SUBTOTAL(109,Bolsausados[Resto]) -> 21954.318 | L12: =SUBTOTAL(109,Bolsausados[Necesidad]) -> 42339
B14: ACTIVOS TOTALES
D16: INVERSIONES | E16: VALOR | I16: JUBILACIÓN | J16: VALOR
D17: ACCIONES | E17: 15000 | I17: PENSIÓN
D18: BONOS | I18: CUENTAS IRA
D19: INVERSIONES EN FONDOS MUTUOS | I19: CUENTAS KEOGH
D20: PARTICIPACIONES SOCIALES | I20: 401K | J20: 46000
D21: OTRAS INVERSIONES | I21: SEP
I22: ESOP
D23: SUBTOTAL | E23: =SUBTOTAL(109,tblInversiones[VALOR]) -> 15000 | I23: SUBTOTAL | J23: =SUBTOTAL(109,tblJubilación[VALOR]) -> 46000

Sheet I9B1a
B2: BOLSA I9B1a | H2: RESUMEN DE LA BOLSA NETO
D4: BOLSA I9B1a | E4: Tope | H4: BOLSA I9B1a | I4: Usados | J4: Resto
D5: Gerencia | E5: 7211.7005 | H5: Gerencia | I5: =VLOOKUP(tblAsegurado[[#This Row],[BOLSA I9B1a]],Cálculos!$H$4:$I$10,2,FALSE) -> 2421 | J5: =tblNoAsegurado[[#This Row],[Tope]]-tblAsegurado[[#This Row],[Usados]] -> 4790.7005
D6: Dirección Médica | E6: 86540.406 | H6: Dirección Médica | I6: =VLOOKUP(tblAsegurado[[#This Row],[BOLSA I9B1a]],Cálculos!$H$4:$I$10,2,FALSE) -> 15779 | J6: =tblNoAsegurado[[#This Row],[Tope]]-tblAsegurado[[#This Row],[Usados]] -> 70761.406
D7: Dirección Enfermería | E7: 284280.58 | H7: DIRECCIÓN DE ENFERMERÍA | I7: =VLOOKUP(tblAsegurado[[#This Row],[BOLSA I9B1a]],Cálculos!$H$4:$I$10,2,FALSE) -> 256833 | J7: =tblNoAsegurado[[#This Row],[Tope]]-tblAsegurado[[#This Row],[Usados]] -> 27447.581
D8: Dirección Planificación y Gestión RREE | E8: 23728.821 | H8: Dirección Planificación y Gestión RREE | I8: =VLOOKUP(tblAsegurado[[#This Row],[BOLSA I9B1a]],Cálculos!$H$4:$I$10,2,FALSE) -> 22620 | J8: =tblNoAsegurado[[#This Row],[Tope]]-tblAsegurado[[#This Row],[Usados]] -> 1108.821
D9: Dirección Ingenería, Infraestructuras y Tecnologías | E9: 11166.504 | H9: Dirección Ingeniería, Infraestructura y Tecnologías | I9: =VLOOKUP(tblAsegurado[[#This Row],[BOLSA I9B1a]],Cálculos!$H$4:$I$10,2,FALSE) -> 8028 | J9: =tblNoAsegurado[[#This Row],[Tope]]-tblAsegurado[[#This Row],[Usados]] -> 3138.504
D10: Dirección Servicios Generales | E10: 42339.661 | H10: Dirección Servicios Generales | I10: =VLOOKUP(tblAsegurado[[#This Row],[BOLSA I9B1a]],Cálculos!$H$4:$I$10,2,FALSE) -> 53410 | J10: =tblNoAsegurado[[#This Row],[Tope]]-tblAsegurado[[#This Row],[Usados]] -> -11070.339
D11: Dirección RRHH | E11: 7444.336 | H11: DIRECCIÓN DE RR.HH. | I11: =VLOOKUP(tblAsegurado[[#This Row],[BOLSA I9B1a]],Cálculos!$H$4:$I$10,2,FALSE) -> 4504 | J11: =tblNoAsegurado[[#This Row],[Tope]]-tblAsegurado[[#This Row],[Usados]] -> 2940.336
B12: =PasivosTotales -> 462712.01 | D12: SUBTOTAL | E12: =SUBTOTAL(109,tblNoAsegurado[Tope]) -> 462712.01 | H12: SUBTOTAL | I12: =SUBTOTAL(109,tblAsegurado[Usados]) -> 363595 | J12: =SUBTOTAL(109,tblAsegurado[Resto]) -> 99117.01
B14: ACTIVOS TOTALES

Sheet Cálculos
A1: Bolsa | B1: Tope | D1: T.Nombrto | E1: N91c | H1: T.Nombrto | I1: S9b1a
A2: Gerencia | B2: 1940.8325
A3: Dirección Médica | B3: 23289.99 | D3: Etiquetas de fila | E3: Suma de Días | F3: Suma de Necesidad | H3: Etiquetas de fila | I3: Suma de Días
A4: Dirección Enfermería | B4: 76506.365 | D4: DIRECCIÓN DE ENFERMERÍA | E4: 34607 | F4: 18822 | H4: DIRECCIÓN DE ENFERMERÍA | I4: 256833
A5: Dirección Planificación y Gestión RREE | B5: 6385.965 | D5: DIRECCIÓN DE RR.HH. | E5: 216 | F5: 149 | H5: DIRECCIÓN DE RR.HH. | I5: 4504
A6: Dirección Ingenería, Infraestructuras y Tecnologías | B6: 3005.16 | D6: Dirección Ingeniería, Infraestructura y Tecnologías | E6: 8645 | F6: 4520 | H6: Dirección Ingeniería, Infraestructura y Tecnologías | I6: 8028
A7: Dirección Servicios Generales | B7: 11394.565 | D7: DIRECCIÓN MÉDICA | E7: 33969 | F7: 9089 | H7: DIRECCIÓN MÉDICA | I7: 15779
A8: Dirección RRHH | B8: 2003.44 | D8: Dirección Planificación y Gestión RREE | E8: 5873 | F8: 1698 | H8: Dirección Planificación y Gestión RREE | I8: 22620
A9: SUBTOTAL | B9: 124526.32 | D9: Dirección Servicios Generales | E9: 13679 | F9: 6317 | H9: Dirección Servicios Generales | I9: 53410
D10: GERENCIA | E10: 5583 | F10: 1744 | H10: GERENCIA | I10: 2421
D11: Total general | E11: 102572 | F11: 42339 | H11: Total general | I11: 363595
A14: Bolsa | B14: Tope
A15: I91b | B15: 0
A16: I91c | B16: 125215
A17: I9B1a | B17: 465271
A18: I9B1b | B18: 64
A19: I9B1c | B19: 0
A20: SUBTOTAL | B20: =SUBTOTAL(109,B15:B19) -> 590550
