Workbook
Name ActivosTotales: Cálculos!$B$9
Name Imprimir_Área: [1]Dashboard!$A$1:$H$19
Name PasivosTotales: tblNoAsegurado10[[#Totals],[Tope]]
Name PasivosTotales: tblNoAsegurado[[#Totals],[Tope]]
Name PatrimonioNeto: Cálculos!$B$9

Sheet 2026
A1: NºPer. | B1: Desde* | C1: Hasta* | D1: Necesidad | E1: NºProp. | F1: Nombrto/Contrato | G1: Razón de Alta | H1: Plaza | I1: RJ | J1: Cláusula | K1: T.Nombrto | L1: Días | M1: Días-N | N1: Puesto trabajo | O1: GFH | P1: Dirección | Q1: NºPer.Sust | R1: DNI.Sust | S1: Nombre Sustituido | T1: Puesto Sustitutido | U1: F_Inicio | V1: F_Fin | W1: F_Necesidad
A2: 206656 | B2: 46023 | C2: 46023 | D2: false | E2: 174955 | F2: TEMPORAL. T. COM. INTER. N. ESTA | G2: MES ACTUAL - INCAPACIDAD TEMPORAL | H2: G AUXILIAR ADMINISTRATIVO F. ADMVA | I2: E | J2: S_9B_1A | K2: S9B1A | L2: 1 | M2: 0 | N2: AUXILIAR ADMINISTRATIVO | O2: ALMACÉN DE COMESTIBLES - ECONOMATO | P2: DIRECCIÓN DE SERVICIOS GENERALES | Q2: 363662 | R2: 79063496F | S2: GALVAN ALMENARA, JOSE FERNANDO | T2: AUXILIAR ADMINISTRATIVO | U2: 46023 | V2: 46023 | W2: =(V2-U2)+1 -> 1
A3: 264083 | B3: 46023 | C3: 46023 | D3: false | E3: 175233 | F3: TEMPORAL. T. COM. INTER. N. ESTA | G3: MES ACTUAL - INCAPACIDAD TEMPORAL | H3: AUXILIAR DE ENFERMERÍA | I3: E | J3: S_9B_1A | K3: S9B1A | L3: 1 | M3: 0 | N3: AUXILIAR DE ENFERMERÍA | O3: PLANTA 4ª PAR - HOSP.EDIF.A | P3: DIRECCIÓN DE ENFERMERÍA | Q3: 357307 | R3: 45446641K | S3: VELAZQUEZ GUTIERREZ, EMILIA PILAR | T3: AUXILIAR DE ENFERMERÍA | U3: 46023 | V3: 46023 | W3: =(V3-U3)+1 -> 1
A4: 388396 | B4: 46023 | C4: 46023 | D4: false | E4: 168478 | F4: TEMPORAL. T. COMPLETO. N. ESTATU | G4: ACUMULACION DE TAREAS | H4: FEA CIRUGÍA ORTOPÉDICA Y TRAUMATOLOGÍA | I4: E | J4: I_9_1C | K4: N91C | L4: 1 | M4: 0 | N4: FEA CIRUGÍA ORTOPÉDICA Y TRAUMATOLOGÍA | O4: P.MÉDICO TRAUMA | P4: DIRECCIÓN MÉDICA | Q4: 0 | U4: 46023 | V4: 46023 | W4: =(V4-U4)+1 -> 1
A5: 246568 | B5: 46023 | C5: 46023 | D5: false | E5: 173782 | F5: TEMPORAL. T. COM. INTER. N. ESTA | G5: LIBRE DISPOSICION | H5: LAVANDERO/A | I5: E | J5: S_9B_1AV | K5: S9B1A | L5: 1 | M5: 0 | N5: LAVANDERIA | O5: LAVANDERÍA HOSP.DEL TORAX | P5: DIRECCIÓN DE SERVICIOS GENERALES | Q5: 394450 | R5: 79086389S | S5: GARCIA FRANQUIS, DAVINIA | U5: 46023 | V5: 46023 | W5: =(V5-U5)+1 -> 1
A6: 273291 | B6: 46023 | C6: 46024 | D6: false | E6: 166191 | F6: TEMPORAL. T. COM. INTER. N. ESTA | G6: MES ACTUAL - INCAPACIDAD TEMPORAL | H6: AUXILIAR DE ENFERMERÍA | I6: E | J6: S_9B_1A | K6: S9B1A | L6: 2 | M6: 0 | N6: AUXILIAR DE ENFERMERÍA | O6: PLANTILLA VOLANTE DEL EAA (EDIFICIO DE ACTIVIDADES | P6: DIRECCIÓN DE ENFERMERÍA | Q6: 311907 | R6: 42063809Y | S6: HERRANZ GOMEZ, MARIA CANDELARIA | T6: AUXILIAR DE ENFERMERÍA | U6: 46023 | V6: 46024 | W6: =(V6-U6)+1 -> 2
A7: 271144 | B7: 46023 | C7: 46024 | D7: false | E7: 172724 | F7: TEMPORAL. T. COM. INTER. N. ESTA | G7: MES ACTUAL - INCAPACIDAD TEMPORAL | H7: AUXILIAR DE ENFERMERÍA | I7: E | J7: S_9B_1A | K7: S9B1A | L7: 2 | M7: 0 | N7: AUXILIAR DE ENFERMERÍA | O7: PLANTA 8ª IMPAR - HOSP.EDIF.A | P7: DIRECCIÓN DE ENFERMERÍA | Q7: 298172 | R7: 79354565B | S7: MOYA ZURITA, EVELIN PAMELA | T7: AUXILIAR DE ENFERMERÍA | U7: 46023 | V7: 46024 | W7: =(V7-U7)+1 -> 2
A8: 240038 | B8: 46023 | C8: 46024 | D8: false | E8: 175480 | F8: TEMPORAL. T. COM. INTER. N. ESTA | G8: MES ACTUAL - INCAPACIDAD TEMPORAL | H8: ENFERMERO/A | I8: E | J8: S_9B_1A | K8: S9B1A | L8: 2 | M8: 0 | N8: ENFERMERA/O | O8: U.V.I. | P8: DIRECCIÓN DE ENFERMERÍA | Q8: 351642 | R8: 43824205M | S8: MENDOZA MENDOZA, MARIA JOSE | T8: ENFERMERA/O | U8: 46023 | V8: 46024 | W8: =(V8-U8)+1 -> 2
A9: 295908 | B9: 46023 | C9: 46024 | D9: false | E9: 175310 | F9: TEMPORAL. T. COM. INTER. N. ESTA | G9: MES ACTUAL - INCAPACIDAD TEMPORAL | H9: AUXILIAR DE ENFERMERÍA | I9: E | J9: S_9B_1A | K9: S9B1A | L9: 2 | M9: 0 | N9: AUXILIAR DE ENFERMERÍA | O9: EXPLORAC.NEUROFISIOLOGIA | P9: DIRECCIÓN DE ENFERMERÍA | Q9: 379123 | R9: 78649600L | S9: FERNANDEZ ESPINOZA, ISABEL SARAY | U9: 46023 | V9: 46024 | W9: =(V9-U9)+1 -> 2
A10: 304586 | B10: 46023 | C10: 46024 | D10: false | E10: 173854 | F10: TEMPORAL. T. COM. INTER. N. ESTA | G10: MES ACTUAL - INCAPACIDAD TEMPORAL | H10: AUXILIAR DE ENFERMERÍA | I10: E | J10: S_9B_1A | K10: S9B1A | L10: 2 | M10: 0 | N10: AUXILIAR DE ENFERMERÍA | O10: DIETÉTICA Y NUTRICIÓN | P10: DIRECCIÓN DE ENFERMERÍA | Q10: 290946 | R10: 78625537Z | S10: GUTIERREZ ALONSO, MARIA YURENA | U10: 46023 | V10: 46024 | W10: =(V10-U10)+1 -> 2
A11: 218106 | B11: 46023 | C11: 46024 | D11: false | E11: 175598 | F11: TEMPORAL. T. COM. INTER. N. ESTA | G11: MES ACTUAL - INCAPACIDAD TEMPORAL | H11: LIMPIADOR/A | I11: E | J11: S_9B_1A | K11: S9B1A | L11: 2 | M11: 0 | N11: LIMPIADORA | O11: SUPLENCIAS LIMPIEZA | P11: DIRECCIÓN DE SERVICIOS GENERALES | Q11: 277802 | R11: 43814704A | S11: JAÑEZ JIMENEZ, GEMA | T11: LIMPIADORA | U11: 46023 | V11: 46024 | W11: =(V11-U11)+1 -> 2
A12: 366231 | B12: 46023 | C12: 46024 | D12: false | E12: 173137 | F12: TEMPORAL. T. COM. INTER. N. ESTA | G12: MES ACTUAL - INCAPACIDAD TEMPORAL | H12: ENFERMERO/A | I12: E | J12: S_9B_1A | K12: S9B1A | L12: 2 | M12: 0 | N12: ENFERMERA/O | O12: UNIDAD HOSPITALIZACIÓN A DOMICILIO - HN | P12: DIRECCIÓN DE ENFERMERÍA | Q12: 367396 | R12: 78570327G | S12: MARTIN GARCIA, ANA ISABEL | T12: ENFERMERA/O | U12: 46023 | V12: 46024 | W12: =(V12-U12)+1 -> 2
A13: 278261 | B13: 46023 | C13: 46024 | D13: false | E13: 168561 | F13: TEMPORAL. T. COMPLETO. N. ESTATU | G13: ACUMULACION DE TAREAS | H13: FEA CARDIOLOGÍA | I13: E | J13: I_9_1C | K13: N91C | L13: 2 | M13: 0 | N13: FEA CARDIOLOGÍA | O13: P.MÉDICO CARDIOLOGÍA | P13: DIRECCIÓN MÉDICA | Q13: 0 | U13: 46023 | V13: 46024 | W13: =(V13-U13)+1 -> 2
A14: 265854 | B14: 46023 | C14: 46024 | D14: false | E14: 174158 | F14: TEMPORAL. T. COM. INTER. N. ESTA | G14: MES ACTUAL - INCAPACIDAD TEMPORAL | H14: ENFERMERO/A | I14: E | J14: S_9B_1A | K14: S9B1A | L14: 2 | M14: 0 | N14: ENFERMERA/O | O14: LAB.HEMOT.Y BCO.SANGRE | P14: DIRECCIÓN DE ENFERMERÍA | Q14: 327773 | R14: 78407957Z | S14: MESA SIVERIO, JESUS EULOGIO | T14: ENFERMERA/O | U14: 46023 | V14: 46024 | W14: =(V14-U14)+1 -> 2
A15: 394442 | B15: 46023 | C15: 46024 | D15: false | E15: 175201 | F15: TEMPORAL. T. COM. INTER. N. ESTA | G15: MES ACTUAL - INCAPACIDAD TEMPORAL | H15: AUXILIAR DE ENFERMERÍA | I15: E | J15: S_9B_1A | K15: S9B1A | L15: 2 | M15: 0 | N15: AUXILIAR DE ENFERMERÍA | O15: PLANTA 3ª/4ª URA | P15: DIRECCIÓN DE ENFERMERÍA | Q15: 261451 | R15: 51165292K | S15: PEREZ IZQUIERDO, NEREA | T15: AUXILIAR DE ENFERMERÍA | U15: 46023 | V15: 46024 | W15: =(V15-U15)+1 -> 2
A16: 265414 | B16: 46023 | C16: 46024 | D16: false | E16: 175290 | F16: TEMPORAL. T. COM. INTER. N. ESTA | G16: MES ACTUAL - INCAPACIDAD TEMPORAL | H16: AUXILIAR DE ENFERMERÍA | I16: E | J16: S_9B_1A | K16: S9B1A | L16: 2 | M16: 0 | N16: AUXILIAR DE ENFERMERÍA | O16: PLANTA 4ª - HOSPITALIZACIÓN EDIF. D | P16: DIRECCIÓN DE ENFERMERÍA | Q16: 341732 | R16: 42092314Z | S16: CASTILLO LEON, JOSEFINA | T16: AUXILIAR DE ENFERMERÍA | U16: 46023 | V16: 46024 | W16: =(V16-U16)+1 -> 2
A17: 379807 | B17: 46023 | C17: 46024 | D17: false | E17: 175287 | F17: TEMPORAL. T. COM. INTER. N. ESTA | G17: MES ACTUAL - INCAPACIDAD TEMPORAL | H17: TERAPEUTA OCUPACIONAL | I17: E | J17: S_9B_1A | K17: S9B1A | L17: 2 | M17: 0 | N17: TERAPEUTA OCUPACIONAL | O17: LABORTERAPIA AGUDOS | P17: DIRECCIÓN DE ENFERMERÍA | Q17: 214045 | R17: 74686418J | S17: HURTADO JIMENEZ, ANA ISABEL | T17: TERAPEUTA OCUPACIONAL | U17: 46023 | V17: 46024 | W17: =(V17-U17)+1 -> 2
A18: 246253 | B18: 46023 | C18: 46024 | D18: false | E18: 175220 | F18: TEMPORAL. T. COM. INTER. N. ESTA | G18: MES ACTUAL - INCAPACIDAD TEMPORAL | H18: AUXILIAR DE ENFERMERÍA | I18: E | J18: S_9B_1A | K18: S9B1A | L18: 2 | M18: 0 | N18: AUXILIAR DE ENFERMERÍA | O18: UDAD.HEMODÍALISIS | P18: DIRECCIÓN DE ENFERMERÍA | Q18: 301864 | R18: 42065567Q | S18: HORMIGA ESTRADA, JOSE ANGEL | T18: AUXILIAR DE ENFERMERÍA | U18: 46023 | V18: 46024 | W18: =(V18-U18)+1 -> 2
A19: 268402 | B19: 46023 | C19: 46024 | D19: false | E19: 173951 | F19: TEMPORAL. T. COM. INTER. N. ESTA | G19: VACACIONES Y LIBRANZAS | H19: ENFERMERO/A | I19: E | J19: S_9B_1A | K19: S9B1A | L19: 2 | M19: 0 | N19: ENFERMERA/O | O19: BLOQUE QUIRURGICO CMA | P19: DIRECCIÓN DE ENFERMERÍA | Q19: 318105 | R19: 42083681Y | S19: GUTIERREZ MARQUEZ, MARIA GEMMA | T19: SUPERVISOR/A DE UNIDAD | U19: 46023 | V19: 46024 | W19: =(V19-U19)+1 -> 2
A20: 214420 | B20: 46023 | C20: 46024 | D20: false | E20: 170965 | F20: TEMPORAL. T. COM. INTER. N. ESTA | G20: MES ACTUAL - INCAPACIDAD TEMPORAL | H20: TÉC ESPECIALISTA / LABORATORIO | I20: E | J20: S_9B_1A | K20: S9B1A | L20: 2 | M20: 0 | N20: TÉCNICO ESPECIALISTA LABORATORIO | O20: LABORATORIO CENTRAL | P20: DIRECCIÓN DE ENFERMERÍA | Q20: 339002 | R20: 43821293Z | S20: JORGE ARTEAGA, MARIA JESUS | T20: TÉCNICO ESPECIALISTA LABORATORIO | U20: 46023 | V20: 46024 | W20: =(V20-U20)+1 -> 2
A21: 305467 | B21: 46023 | C21: 46024 | D21: false | E21: 175446 | F21: TEMPORAL. T. COM. INTER. N. ESTA | G21: MES ACTUAL - INCAPACIDAD TEMPORAL | H21: AUXILIAR DE ENFERMERÍA | I21: E | J21: S_9B_1A | K21: S9B1A | L21: 2 | M21: 0 | N21: AUXILIAR DE ENFERMERÍA | O21: PLANTA 1ª - HOSPITALIZACIÓN EDIF. D | P21: DIRECCIÓN DE ENFERMERÍA | Q21: 367978 | R21: 78859096P | S21: RODRIGUES AFONSO, ROSILENE | T21: AUXILIAR DE ENFERMERÍA | U21: 46023 | V21: 46024 | W21: =(V21-U21)+1 -> 2
A22: 261451 | B22: 46023 | C22: 46024 | D22: false | E22: 174898 | F22: TEMPORAL. T. COM. INTER. N. ESTA | G22: MES ACTUAL - INCAPACIDAD TEMPORAL | H22: AUXILIAR DE ENFERMERÍA | I22: E | J22: S_9B_1A | K22: S9B1A | L22: 2 | M22: 0 | N22: AUXILIAR DE ENFERMERÍA | O22: PLANTA 3ª/4ª URA | P22: DIRECCIÓN DE ENFERMERÍA | Q22: 241702 | R22: 42191242L | S22: PEREZ LORENZO, NIRA | T22: AUXILIAR DE ENFERMERÍA | U22: 46023 | V22: 46024 | W22: =(V22-U22)+1 -> 2
A23: 229155 | B23: 46023 | C23: 46026 | D23: false | E23: 174984 | F23: TEMPORAL. T. COMPLETO. N. ESTATU | G23: ACUMULACION DE TAREAS | H23: TÉC ESPECIALISTA / RADIODIAGNÓSTICO | I23: E | J23: I_9_1C | K23: N91C | L23: 4 | M23: 0 | N23: TÉCNICO ESPECIALISTA RADIODIAGNÓSTICO | O23: RADIODIAGNOSTICO | P23: DIRECCIÓN DE ENFERMERÍA | Q23: 0 | U23: 46023 | V23: 46026 | W23: =(V23-U23)+1 -> 4
A24: 354274 | B24: 46023 | C24: 46026 | D24: false | E24: 170287 | F24: TEMPORAL. T. COM. INTER. N. ESTA | G24: MES ACTUAL - INCAPACIDAD TEMPORAL | H24: LIMPIADOR/A | I24: E | J24: S_9B_1A | K24: S9B1A | L24: 4 | M24: 0 | N24: LIMPIADORA | O24: LIMPIEZA | P24: DIRECCIÓN DE SERVICIOS GENERALES | Q24: 256125 | R24: 42220411R | S24: CASTRO FERNANDEZ, YVONNE | T24: LIMPIADORA | U24: 46023 | V24: 46026 | W24: =(V24-U24)+1 -> 4
A25: 203345 | B25: 46023 | C25: 46026 | D25: false | E25: 173002 | F25: TEMPORAL. T. COM. INTER. N. ESTA | G25: MES ACTUAL - INCAPACIDAD TEMPORAL | H25: AUXILIAR DE ENFERMERÍA | I25: E | J25: S_9B_1A | K25: S9B1A | L25: 4 | M25: 0 | N25: AUXILIAR DE ENFERMERÍA | O25: PLANTA 1ª PAR - HOSP.EDIF.A | P25: DIRECCIÓN DE ENFERMERÍA | Q25: 304894 | R25: 78639822Q | S25: VILLA ROMERO, LORENA | T25: AUXILIAR DE ENFERMERÍA | U25: 46023 | V25: 46026 | W25: =(V25-U25)+1 -> 4
A26: 334213 | B26: 46023 | C26: 46027 | D26: false | E26: 173779 | F26: TEMPORAL. T. COM. INTER. N. ESTA | G26: MES ACTUAL - INCAPACIDAD TEMPORAL | H26: AUXILIAR DE ENFERMERÍA | I26: E | J26: S_9B_1A | K26: S9B1A | L26: 5 | M26: 0 | N26: AUXILIAR DE ENFERMERÍA | O26: PLANTILLA VOLANTE DEL EAA (EDIFICIO DE ACTIVIDADES | P26: DIRECCIÓN DE ENFERMERÍA | Q26: 353760 | R26: 43808780J | S26: ALONSO CARBALLO, CANDELARIA DACIL | T26: AUXILIAR DE ENFERMERÍA | U26: 46023 | V26: 46027 | W26: =(V26-U26)+1 -> 5
A27: 249715 | B27: 46023 | C27: 46027 | D27: false | E27: 173835 | F27: TEMPORAL. T. COM. INTER. N. ESTA | G27: MES ACTUAL - INCAPACIDAD TEMPORAL | H27: AUXILIAR DE ENFERMERÍA | I27: E | J27: S_9B_1A | K27: S9B1A | L27: 5 | M27: 0 | N27: AUXILIAR DE ENFERMERÍA | O27: PLANTA 1ª PAR - HOSP.EDIF.A | P27: DIRECCIÓN DE ENFERMERÍA | Q27: 222124 | R27: 45457791Q | S27: DE DIOS FAGUNDO, MARIA ALEJANDRA | T27: AUXILIAR DE ENFERMERÍA | U27: 46023 | V27: 46027 | W27: =(V27-U27)+1 -> 5
A28: 341254 | B28: 46023 | C28: 46027 | D28: false | E28: 175603 | F28: TEMPORAL. T. COM. INTER. N. ESTA | G28: MES ACTUAL - INCAPACIDAD TEMPORAL | H28: AUXILIAR DE ENFERMERÍA | I28: E | J28: S_9B_1A | K28: S9B1A | L28: 5 | M28: 0 | N28: AUXILIAR DE ENFERMERÍA | O28: URGENCIAS | P28: DIRECCIÓN DE ENFERMERÍA | Q28: 295509 | R28: 54054030M | S28: BAJET FERNANDEZ-ARDISANA, PATRICIA | T28: AUXILIAR DE ENFERMERÍA | U28: 46023 | V28: 46027 | W28: =(V28-U28)+1 -> 5
A29: 222124 | B29: 46023 | C29: 46027 | D29: false | E29: 169667 | F29: TEMPORAL. T. COM. INTER. N. ESTA | G29: MES ACTUAL - INCAPACIDAD TEMPORAL | H29: AUXILIAR DE ENFERMERÍA | I29: E | J29: S_9B_1A | K29: S9B1A | L29: 5 | M29: 0 | N29: AUXILIAR DE ENFERMERÍA | O29: PLANTA 1ª PAR - HOSP.EDIF.A | P29: DIRECCIÓN DE ENFERMERÍA | Q29: 247525 | R29: 45456181Q | S29: CAMPO DIAZ LEDESMA, MARIA ADELA | T29: AUXILIAR DE ENFERMERÍA | U29: 46023 | V29: 46027 | W29: =(V29-U29)+1 -> 5
A30: 251854 | B30: 46023 | C30: 46027 | D30: false | E30: 173723 | F30: TEMPORAL. T. COM. INTER. N. ESTA | G30: MES ACTUAL - INCAPACIDAD TEMPORAL | H30: AUXILIAR DE ENFERMERÍA | I30: E | J30: S_9B_1A | K30: S9B1A | L30: 5 | M30: 0 | N30: AUXILIAR DE ENFERMERÍA | O30: ESTERILIZACIÓN | P30: DIRECCIÓN DE ENFERMERÍA | Q30: 380974 | R30: 45444569L | S30: GAMEZ RAMOS, MARIA AUXILIADORA | T30: AUXILIAR DE ENFERMERÍA | U30: 46023 | V30: 46027 | W30: =(V30-U30)+1 -> 5
A31: 376058 | B31: 46023 | C31: 46027 | D31: false | E31: 173126 | F31: TEMPORAL. T. COM. INTER. N. ESTA | G31: MES ACTUAL - INCAPACIDAD TEMPORAL | H31: ENFERMERO/A | I31: E | J31: S_9B_1A | K31: S9B1A | L31: 5 | M31: 0 | N31: ENFERMERA/O | O31: PLANTA 7ª PAR - HOSP.EDIF.A | P31: DIRECCIÓN DE ENFERMERÍA | Q31: 367572 | R31: 78628266Y | S31: RUIZ MESA, LOURDES | T31: ENFERMERA/O | U31: 46023 | V31: 46027 | W31: =(V31-U31)+1 -> 5
A32: 296095 | B32: 46023 | C32: 46027 | D32: false | E32: 173657 | F32: TEMPORAL. T. COM. INTER. N. ESTA | G32: MES ACTUAL - INCAPACIDAD TEMPORAL | H32: ENFERMERO/A | I32: E | J32: S_9B_1A | K32: S9B1A | L32: 5 | M32: 0 | N32: ENFERMERA/O | O32: PLANTA 1ª - HOSPITALIZACIÓN EDIF. D | P32: DIRECCIÓN DE ENFERMERÍA | Q32: 339758 | R32: 78673312H | S32: ALVARO AFONSO, MARIA DE LA O | T32: SUPERVISOR/A DE UNIDAD | U32: 46023 | V32: 46027 | W32: =(V32-U32)+1 -> 5
A33: 265414 | B33: 46025 | C33: 46027 | D33: false | E33: 175639 | F33: TEMPORAL. T. COM. INTER. N. ESTA | G33: LIBRE DISPOSICION | H33: AUXILIAR DE ENFERMERÍA | I33: E | J33: S_9B_1A | K33: S9B1A | L33: 3 | M33: 0 | N33: AUXILIAR DE ENFERMERÍA | O33: PLANTA 4ª - HOSPITALIZACIÓN EDIF. D | P33: DIRECCIÓN DE ENFERMERÍA | Q33: 345867 | R33: 78613215C | S33: HERNANDEZ RODRIGUEZ, RAQUEL | T33: AUXILIAR DE ENFERMERÍA | U33: 46025 | V33: 46027 | W33: =(V33-U33)+1 -> 3
A34: 371650 | B34: 46023 | C34: 46028 | D34: false | E34: 173860 | F34: TEMPORAL. T. COM. INTER. N. ESTA | G34: LIBRE DISPOSICION | H34: G ADMINISTRATIVO FUNCIÓN ADMINISTRATIVA | I34: E | J34: S_9B_1AV | K34: S9B1A | L34: 6 | M34: 0 | N34: GRUPO ADMINISTRATIVO | O34: COORDINACIÓN DE INFORMACIÓN | P34: GERENCIA | Q34: 294757 | R34: 42221194W | S34: GONZALEZ VIERA, VERONICA | T34: GRUPO ADMINISTRATIVO | U34: 46023 | V34: 46028 | W34: =(V34-U34)+1 -> 6
A35: 209704 | B35: 46023 | C35: 46028 | D35: false | E35: 163552 | F35: TEMPORAL. T. COM. INTER. N. ESTA | G35: MES ACTUAL - INCAPACIDAD TEMPORAL | H35: COCINERO/A | I35: E | J35: S_9B_1A | K35: S9B1A | L35: 6 | M35: 0 | N35: COCINERO | O35: COCINA | P35: DIRECCIÓN DE SERVICIOS GENERALES | Q35: 373710 | R35: 78569848P | S35: SABINA PEREZ, GUILLERMO MARINO | T35: COCINERO | U35: 46023 | V35: 46028 | W35: =(V35-U35)+1 -> 6
... A44: 201947 | B44: 46023 | C44: 46029 | D44: false | E44: 175066 | F44: TEMPORAL. T. COM. INTER. N. ESTA | G44: MES ACTUAL - INCAPACIDAD TEMPORAL | H44: AUXILIAR DE ENFERMERÍA | I44: E | J44: S_9B_1A | K44: S9B1A | L44: 7 | M44: 0 | N44: AUXILIAR DE ENFERMERÍA | O44: PLANTA 2ª - HOSPITAL DEL NORTE | P44: DIRECCIÓN DE ENFERMERÍA | Q44: 359361 | R44: 78612195N | S44: GARCIA GONZALEZ, MARIA ANGELES | T44: AUXILIAR DE ENFERMERÍA | U44: 46023 | V44: 46029 | W44: =(V44-U44)+1 -> 7
A45: 330563 | B45: 46023 | C45: 46029 | D45: false | E45: 168560 | F45: TEMPORAL. T. COMPLETO. N. ESTATU | G45: ACUMULACION DE TAREAS | H45: FEA HEMATOLOGÍA Y HEMOTERAPIA | I45: E | J45: I_9_1C | K45: N91C | L45: 7 | M45: 0 | N45: FEA HEMATOLOGÍA Y HEMOTERAPIA | O45: P.MÉDICO HEMATOLOGÍA CLÍNICA | P45: DIRECCIÓN MÉDICA | Q45: 0 | U45: 46023 | V45: 46029 | W45: =(V45-U45)+1 -> 7
A46: 278362 | B46: 46023 | C46: 46029 | D46: false | E46: 174770 | F46: TEMPORAL. T. COM. INTER. N. ESTA | H46: AUXILIAR DE ENFERMERÍA | I46: E | J46: S_9B_1A | K46: S9B1A | L46: 7 | M46: 0 | N46: AUXILIAR DE ENFERMERÍA | O46: PLANTA 2ª CENTRAL A - EDIF.B | P46: DIRECCIÓN DE ENFERMERÍA | Q46: 365390 | R46: 78620644C | S46: BELTRAN DORTA, VERONICA | T46: AUXILIAR DE ENFERMERÍA | U46: 46023 | V46: 46029 | W46: =(V46-U46)+1 -> 7
A47: 229806 | B47: 46023 | C47: 46029 | D47: false | E47: 175328 | F47: TEMPORAL. T. COM. INTER. N. ESTA | G47: MES ACTUAL - INCAPACIDAD TEMPORAL | H47: AUXILIAR DE ENFERMERÍA | I47: E | J47: S_9B_1A | K47: S9B1A | L47: 7 | M47: 0 | N47: AUXILIAR DE ENFERMERÍA | O47: UDAD.SALUD MENTAL DE TACORONTE | P47: DIRECCIÓN DE ENFERMERÍA | Q47: 224380 | R47: 42093891G | S47: ROSA GONZALEZ, LIDIA | T47: AUXILIAR DE ENFERMERÍA | U47: 46023 | V47: 46029 | W47: =(V47-U47)+1 -> 7
A48: 206974 | B48: 46023 | C48: 46029 | D48: false | E48: 175049 | F48: TEMPORAL. T. COM. INTER. N. ESTA | G48: MES ACTUAL - INCAPACIDAD TEMPORAL | H48: AUXILIAR DE ENFERMERÍA | I48: E | J48: S_9B_1A | K48: S9B1A | L48: 7 | M48: 0 | N48: AUXILIAR DE ENFERMERÍA | O48: RADIODIAGNOSTICO | P48: DIRECCIÓN DE ENFERMERÍA | Q48: 382786 | R48: 54061526A | S48: MORENO GONZALEZ, DESIREE | T48: AUXILIAR DE ENFERMERÍA | U48: 46023 | V48: 46029 | W48: =(V48-U48)+1 -> 7
...

Sheet Panel
B2: PANEL | G2: RESUMEN DE LA BOLSA NETO
B11: =125215+464271 -> 589486 | D11: =ActivosTotales -> 124526.32 | G11: =PasivosTotales -> 462712.01
B12: BOLSA NETO | D12: Bolsa I91c | G12: Bolsa I9B1a
B13: Bolsa I91b | D13: Dirección Planificación y Gestión RREE | G13: Dirección Planificación y Gestión RREE
B14: 32469 | D14: Dirección Enfermería | G14: Dirección Enfermería
D15: Dirección Ingeneria, Infraestrutura y Tecn. | G15: Dirección Ingeneria, Infraestrutura y Tecn.
D16: Dirección Servicios Generales | G16: Dirección Servicios Generales
D17: Dirección Médica | G17: Dirección Médica
D18: Dirección RRHH | G18: Dirección RRHH
D19: Gerencia | G19: Gerencia

Sheet I91b
B2: BOLSA I91b | H2: RESUMEN DE LA BOLSA NETO
D4: BOLSA I91b | E4: Tope | H4: BOLSA I91b | I4: Usados | J4: Resto
D5: Gerencia | E5: =VLOOKUP(tblNoAsegurado10[[#This Row],[BOLSA I91b]],Bolsatotaldirecciones13[#All],2,FALSE) -> 503.2695 | H5: Gerencia | I5: =IFERROR(VLOOKUP(tblAsegurado12[[#This Row],[BOLSA I91b]],Cálculos!$D$14:$F$21,2,FALSE),0) -> 423 | J5: =tblNoAsegurado10[[#This Row],[Tope]]-tblAsegurado12[[#This Row],[Usados]] -> 80.2695
D6: Dirección Médica | E6: =VLOOKUP(tblNoAsegurado10[[#This Row],[BOLSA I91b]],Bolsatotaldirecciones13[#All],2,FALSE) -> 6042.4809 | H6: Dirección Médica | I6: =IFERROR(VLOOKUP(tblAsegurado12[[#This Row],[BOLSA I91b]],Cálculos!$D$14:$F$21,2,FALSE),0) -> 24639 | J6: =tblNoAsegurado10[[#This Row],[Tope]]-tblAsegurado12[[#This Row],[Usados]] -> -18596.519
D7: Dirección Enfermería | E7: =VLOOKUP(tblNoAsegurado10[[#This Row],[BOLSA I91b]],Bolsatotaldirecciones13[#All],2,FALSE) -> 19832.065 | H7: DIRECCIÓN DE ENFERMERÍA | I7: =IFERROR(VLOOKUP(tblAsegurado12[[#This Row],[BOLSA I91b]],Cálculos!$D$14:$F$21,2,FALSE),0) -> 2170 | J7: =tblNoAsegurado10[[#This Row],[Tope]]-tblAsegurado12[[#This Row],[Usados]] -> 17662.065
D8: Dirección Planificación y Gestión RREE | E8: =VLOOKUP(tblNoAsegurado10[[#This Row],[BOLSA I91b]],Bolsatotaldirecciones13[#All],2,FALSE) -> 1883.202 | H8: DIRECCIÓN DE PLANIFIFCACIÓN Y GESTIÓN DE RR.EE. | I8: =IFERROR(VLOOKUP(tblAsegurado12[[#This Row],[BOLSA I91b]],Cálculos!$D$14:$F$21,2,FALSE),0) -> 0 | J8: =tblNoAsegurado10[[#This Row],[Tope]]-tblAsegurado12[[#This Row],[Usados]] -> 1883.202
D9: Dirección Ingenería, Infraestructuras y Tecnologías | E9: =VLOOKUP(tblNoAsegurado10[[#This Row],[BOLSA I91b]],Bolsatotaldirecciones13[#All],2,FALSE) -> 759.7746 | H9: DIRECCIÓN DE INGENIERÍA, INFRAESTRUCTURAS Y TEC. | I9: =IFERROR(VLOOKUP(tblAsegurado12[[#This Row],[BOLSA I91b]],Cálculos!$D$14:$F$21,2,FALSE),0) -> 0 | J9: =tblNoAsegurado10[[#This Row],[Tope]]-tblAsegurado12[[#This Row],[Usados]] -> 759.7746
D10: Dirección Servicios Generales | E10: =VLOOKUP(tblNoAsegurado10[[#This Row],[BOLSA I91b]],Bolsatotaldirecciones13[#All],2,FALSE) -> 2948.1852 | H10: DIRECCIÓN DE SERVICIOS GENERALES | I10: =IFERROR(VLOOKUP(tblAsegurado12[[#This Row],[BOLSA I91b]],Cálculos!$D$14:$F$21,2,FALSE),0) -> 0 | J10: =tblNoAsegurado10[[#This Row],[Tope]]-tblAsegurado12[[#This Row],[Usados]] -> 2948.1852
D11: Dirección RRHH | E11: =VLOOKUP(tblNoAsegurado10[[#This Row],[BOLSA I91b]],Bolsatotaldirecciones13[#All],2,FALSE) -> 496.7757 | H11: DIRECCIÓN DE RR.HH. | I11: =IFERROR(VLOOKUP(tblAsegurado12[[#This Row],[BOLSA I91b]],Cálculos!$D$14:$F$21,2,FALSE),0) -> 735 | J11: =tblNoAsegurado10[[#This Row],[Tope]]-tblAsegurado12[[#This Row],[Usados]] -> -238.2243
B12: =PasivosTotales -> 32465.753 | D12: SUBTOTAL | E12: =SUBTOTAL(109,tblNoAsegurado10[Tope]) -> 32465.753 | H12: SUBTOTAL | I12: =SUBTOTAL(109,tblAsegurado12[Usados]) -> 27967 | J12: =SUBTOTAL(109,tblAsegurado12[Resto]) -> 4498.7531
B14: ACTIVOS TOTALES

Sheet I91c
B2: BOLSA I91c | I2: RESUMEN DE LA BOLSA NETO
D4: Bolsa I91c | E4: Tope | I4: Bolsa I91c | J4: Usados | K4: Resto | L4: Necesidad
D5: Gerencia | E5: 1940.8325 | I5: Gerencia | J5: =VLOOKUP(Bolsausados[[#This Row],[Bolsa I91c]],Cálculos!$D$4:$F$10,2,FALSE) -> 7232 | K5: =Bolsatope[[#This Row],[Tope]]-Bolsausados[[#This Row],[Usados]] -> -5291.1675 | L5: =VLOOKUP(Bolsausados[[#This Row],[Bolsa I91c]],Cálculos!$D$4:$F$10,3,FALSE) -> 0
D6: Dirección Médica | E6: 23289.99 | I6: Dirección Médica | J6: =VLOOKUP(Bolsausados[[#This Row],[Bolsa I91c]],Cálculos!$D$4:$F$10,2,FALSE) -> 37747 | K6: =Bolsatope[[#This Row],[Tope]]-Bolsausados[[#This Row],[Usados]] -> -14457.01 | L6: =VLOOKUP(Bolsausados[[#This Row],[Bolsa I91c]],Cálculos!$D$4:$F$10,3,FALSE) -> 0
D7: Dirección Enfermería | E7: 76506.365 | I7: DIRECCIÓN DE ENFERMERÍA | J7: =VLOOKUP(Bolsausados[[#This Row],[Bolsa I91c]],Cálculos!$D$4:$F$10,2,FALSE) -> 37192 | K7: =Bolsatope[[#This Row],[Tope]]-Bolsausados[[#This Row],[Usados]] -> 39314.365 | L7: =VLOOKUP(Bolsausados[[#This Row],[Bolsa I91c]],Cálculos!$D$4:$F$10,3,FALSE) -> 0
D8: Dirección Planificación y Gestión RREE | E8: 6385.965 | I8: DIRECCIÓN DE PLANIFIFCACIÓN Y GESTIÓN DE RR.EE. | J8: =VLOOKUP(Bolsausados[[#This Row],[Bolsa I91c]],Cálculos!$D$4:$F$10,2,FALSE) -> 4980 | K8: =Bolsatope[[#This Row],[Tope]]-Bolsausados[[#This Row],[Usados]] -> 1405.965 | L8: =VLOOKUP(Bolsausados[[#This Row],[Bolsa I91c]],Cálculos!$D$4:$F$10,3,FALSE) -> 0
D9: Dirección Ingenería, Infraestructuras y Tecnologías | E9: 3005.16 | I9: DIRECCIÓN DE INGENIERÍA, INFRAESTRUCTURAS Y TEC. | J9: =VLOOKUP(Bolsausados[[#This Row],[Bolsa I91c]],Cálculos!$D$4:$F$10,2,FALSE) -> 9919 | K9: =Bolsatope[[#This Row],[Tope]]-Bolsausados[[#This Row],[Usados]] -> -6913.84 | L9: =VLOOKUP(Bolsausados[[#This Row],[Bolsa I91c]],Cálculos!$D$4:$F$10,3,FALSE) -> 0
D10: Dirección Servicios Generales | E10: 11394.565 | I10: DIRECCIÓN DE SERVICIOS GENERALES | J10: =VLOOKUP(Bolsausados[[#This Row],[Bolsa I91c]],Cálculos!$D$4:$F$10,2,FALSE) -> 14054 | K10: =Bolsatope[[#This Row],[Tope]]-Bolsausados[[#This Row],[Usados]] -> -2659.435 | L10: =VLOOKUP(Bolsausados[[#This Row],[Bolsa I91c]],Cálculos!$D$4:$F$10,3,FALSE) -> 0
D11: Dirección RRHH | E11: 2003.44 | I11: DIRECCIÓN DE RR.HH. | J11: =VLOOKUP(Bolsausados[[#This Row],[Bolsa I91c]],Cálculos!$D$4:$F$10,2,FALSE) -> 984 | K11: =Bolsatope[[#This Row],[Tope]]-Bolsausados[[#This Row],[Usados]] -> 1019.44 | L11: =VLOOKUP(Bolsausados[[#This Row],[Bolsa I91c]],Cálculos!$D$4:$F$10,3,FALSE) -> 0
B12: =ActivosTotales -> 124526.32 | D12: SUBTOTAL | E12: =SUBTOTAL(109,Bolsatope[Tope]) -> 124526.32 | I12: SUBTOTAL | J12: =SUBTOTAL(109,Bolsausados[Usados]) -> 112108 | K12: =SUBTOTAL(109,Bolsausados[Resto]) -> 12418.318 | L12: =SUBTOTAL(109,Bolsausados[Necesidad]) -> 0
B14: ACTIVOS TOTALES
D16: INVERSIONES | E16: VALOR | I16: JUBILACIÓN | J16: VALOR
D17: ACCIONES | E17: 15000 | I17: PENSIÓN
D18: BONOS | I18: CUENTAS IRA
D19: INVERSIONES EN FONDOS MUTUOS | I19: CUENTAS KEOGH
D20: PARTICIPACIONES SOCIALES | I20: 401K | J20: 46000
D21: OTRAS INVERSIONES | I21: SEP
I22: ESOP
D23: SUBTOTAL | E23: =SUBTOTAL(109,tblInversiones[VALOR]) -> 15000 | I23: SUBTOTAL | J23: =SUBTOTAL(109,tblJubilación[VALOR]) -> 46000

Sheet I9B1a
B2: BOLSA I9B1a | H2: RESUMEN DE LA BOLSA NETO
D4: BOLSA I9B1a | E4: Tope | H4: BOLSA I9B1a | I4: Usados | J4: Resto
D5: Gerencia | E5: 7211.7005 | H5: Gerencia | I5: =VLOOKUP(tblAsegurado[[#This Row],[BOLSA I9B1a]],Cálculos!$H$4:$I$10,2,FALSE) -> 2829 | J5: =tblNoAsegurado[[#This Row],[Tope]]-tblAsegurado[[#This Row],[Usados]] -> 4382.7005
D6: Dirección Médica | E6: 86540.406 | H6: Dirección Médica | I6: =VLOOKUP(tblAsegurado[[#This Row],[BOLSA I9B1a]],Cálculos!$H$4:$I$10,2,FALSE) -> 18558 | J6: =tblNoAsegurado[[#This Row],[Tope]]-tblAsegurado[[#This Row],[Usados]] -> 67982.406
D7: Dirección Enfermería | E7: 284280.58 | H7: DIRECCIÓN DE ENFERMERÍA | I7: =VLOOKUP(tblAsegurado[[#This Row],[BOLSA I9B1a]],Cálculos!$H$4:$I$10,2,FALSE) -> 261595 | J7: =tblNoAsegurado[[#This Row],[Tope]]-tblAsegurado[[#This Row],[Usados]] -> 22685.581
D8: Dirección Planificación y Gestión RREE | E8: 23728.821 | H8: DIRECCIÓN DE PLANIFIFCACIÓN Y GESTIÓN DE RR.EE. | I8: =VLOOKUP(tblAsegurado[[#This Row],[BOLSA I9B1a]],Cálculos!$H$4:$I$10,2,FALSE) -> 23579 | J8: =tblNoAsegurado[[#This Row],[Tope]]-tblAsegurado[[#This Row],[Usados]] -> 149.821
D9: Dirección Ingenería, Infraestructuras y Tecnologías | E9: 11166.504 | H9: DIRECCIÓN DE INGENIERÍA, INFRAESTRUCTURAS Y TEC. | I9: =VLOOKUP(tblAsegurado[[#This Row],[BOLSA I9B1a]],Cálculos!$H$4:$I$10,2,FALSE) -> 8879 | J9: =tblNoAsegurado[[#This Row],[Tope]]-tblAsegurado[[#This Row],[Usados]] -> 2287.504
D10: Dirección Servicios Generales | E10: 42339.661 | H10: DIRECCIÓN DE SERVICIOS GENERALES | I10: =VLOOKUP(tblAsegurado[[#This Row],[BOLSA I9B1a]],Cálculos!$H$4:$I$10,2,FALSE) -> 50799 | J10: =tblNoAsegurado[[#This Row],[Tope]]-tblAsegurado[[#This Row],[Usados]] -> -8459.339
D11: Dirección RRHH | E11: 7444.336 | H11: DIRECCIÓN DE RR.HH. | I11: =VLOOKUP(tblAsegurado[[#This Row],[BOLSA I9B1a]],Cálculos!$H$4:$I$10,2,FALSE) -> 4504 | J11: =tblNoAsegurado[[#This Row],[Tope]]-tblAsegurado[[#This Row],[Usados]] -> 2940.336
B12: =PasivosTotales -> 462712.01 | D12: SUBTOTAL | E12: =SUBTOTAL(109,tblNoAsegurado[Tope]) -> 462712.01 | H12: SUBTOTAL | I12: =SUBTOTAL(109,tblAsegurado[Usados]) -> 370743 | J12: =SUBTOTAL(109,tblAsegurado[Resto]) -> 91969.01
B14: ACTIVOS TOTALES

Sheet Cálculos
A1: Bolsa N91C | B1: Tope | D1: T.Nombrto | E1: N91C | H1: T.Nombrto | I1: S9B1A
A2: Gerencia | B2: 1940.8325
A3: Dirección Médica | B3: 23289.99 | D3: Etiquetas de fila | E3: Suma de Días | F3: Suma de Días-N | H3: Etiquetas de fila | I3: Suma de Días
A4: Dirección Enfermería | B4: 76506.365 | D4: DIRECCIÓN DE ENFERMERÍA | E4: 37192 | F4: 0 | H4: DIRECCIÓN DE ENFERMERÍA | I4: 261595
A5: Dirección Planificación y Gestión RREE | B5: 6385.965 | D5: DIRECCIÓN DE INGENIERÍA, INFRAESTRUCTURAS Y TEC. | E5: 9919 | F5: 0 | H5: DIRECCIÓN DE INGENIERÍA, INFRAESTRUCTURAS Y TEC. | I5: 8879
A6: Dirección Ingenería, Infraestructuras y Tecnologías | B6: 3005.16 | D6: DIRECCIÓN DE PLANIFIFCACIÓN Y GESTIÓN DE RR.EE. | E6: 4980 | F6: 0 | H6: DIRECCIÓN DE PLANIFIFCACIÓN Y GESTIÓN DE RR.EE. | I6: 23579
A7: Dirección Servicios Generales | B7: 11394.565 | D7: DIRECCIÓN DE RR.HH. | E7: 984 | F7: 0 | H7: DIRECCIÓN DE RR.HH. | I7: 4504
A8: Dirección RRHH | B8: 2003.44 | D8: DIRECCIÓN DE SERVICIOS GENERALES | E8: 14054 | F8: 0 | H8: DIRECCIÓN DE SERVICIOS GENERALES | I8: 50799
A9: SUBTOTAL | B9: 124526.32 | D9: DIRECCIÓN MÉDICA | E9: 37747 | F9: 0 | H9: DIRECCIÓN MÉDICA | I9: 18558
D10: GERENCIA | E10: 7232 | F10: 0 | H10: GERENCIA | I10: 2829
D11: Total general | E11: 112108 | F11: 0 | H11: Total general | I11: 370743
A14: Bolsa N91b | B14: Tope | D14: T.Nombrto | E14: N91B
A15: Gerencia | B15: =$B$26*B35/100 -> 503.2695
A16: Dirección Médica | B16: =$B$26*B36/100 -> 6042.4809 | D16: Etiquetas de fila | E16: Suma de Días | F16: Suma de Días-N
A17: Dirección Enfermería | B17: =$B$26*B37/100 -> 19832.065 | D17: DIRECCIÓN DE ENFERMERÍA | E17: 2170 | F17: 0
A18: Dirección Planificación y Gestión RREE | B18: =$B$26*B38/100 -> 1883.202 | D18: DIRECCIÓN DE RR.HH. | E18: 735 | F18: 0
A19: Dirección Ingenería, Infraestructuras y Tecnologías | B19: =$B$26*B39/100 -> 759.7746 | D19: DIRECCIÓN MÉDICA | E19: 24639 | F19: 0
A20: Dirección Servicios Generales | B20: =$B$26*B40/100 -> 2948.1852 | D20: GERENCIA | E20: 423 | F20: 0
A21: Dirección RRHH | B21: =$B$26*B41/100 -> 496.7757 | D21: Total general | E21: 27967 | F21: 0
A22: SUBTOTAL | B22: =SUBTOTAL(109,B15:B21) -> 32465.753
A25: Bolsas | B25: Tope
A26: I91b | B26: 32469
A27: I91c | B27: 125215
A28: I9B1a | B28: 465271
A29: I9B1b | B29: 64
A30: I9B1c | B30: 0
A31: SUBTOTAL | B31: =SUBTOTAL(109,B26:B30) -> 623019
A34: Ponderación PO Estatutario | B34: %
A35: Gerencia | B35: 1.55
A36: Dirección Médica | B36: 18.61
A37: Dirección Enfermería | B37: 61.08
A38: Dirección Planificación y Gestión RREE | B38: 5.8
A39: Dirección Ingenería, Infraestructuras y Tecnologías | B39: 2.34
A40: Dirección Servicios Generales | B40: 9.08
A41: Dirección RRHH | B41: 1.53
A42: SUBTOTAL | B42: =SUBTOTAL(109,B35:B41) -> 99.99
